Workbook
Name 所屬金控選項: 來源索引!$H$2:$H$16
Name 業別選項: _xlfn.ANCHORARRAY(來源索引!$F$2)
Name 業者選項: _xlfn.ANCHORARRAY(來源索引!$G$2)
Name 類別選項: 分類說明!$A$5:$A$18

Sheet AI應用場景
A1: 業別 | B1: 業者 | C1: 所屬金控 | D1: 場景 | E1: 類別 | F1: 更新日期
A2: 銀行業 | B2: 富邦金控 | C2: 富邦金 | D2: 智能法遵系統：蒐集外規異動資訊，自動判讀內外規及相關單位關聯，輔助法遵檢視與派發作業。 | E2: 比對 | F2: 46310
A3: 銀行業 | B3: 富邦金控 | C3: 富邦金 | D3: 端點偵測及回應（EDR）資安監控分析：即時監控電腦活動，交叉比對威脅情資。 | E3: 比對 | F3: 46310
A4: 銀行業 | B4: 富邦金控 | C4: 富邦金 | D4: 網路偵測與回應（NDR）：即時側錄與截取網路流量，以機器學習解析異常行為。 | E4: 其它 | F4: 46310
A5: 銀行業 | B5: 臺灣金控 | C5: 臺灣金 | D5: 導入微軟 Copilot，協助文件撰寫、資料分析、簡報製作、資訊摘要及報告初稿，並支援會議紀錄、信件與公文作業。 | E5: M365 Copilot | F5: 46310
A6: 銀行業 | B6: 玉山金控 | C6: 玉山金 | D6: 「金融無塵室」計畫：應用同態加密與雙盲技術，在安全合規環境促成跨行庫、跨產業資料協作，強化聯防識詐。 | E6: 阻詐 | F6: 46310
A7: 銀行業 | B7: 王道銀行 | C7: 未歸類 | D7: 智能客服。 | E7: 智能客服 | F7: 46310
A8: 銀行業 | B8: 連線銀行 | C8: 未歸類 | D8: 防詐預警：已發展四個預警模型，其中兩個具每小時自動 BLOCK 機制。 | E8: 阻詐 | F8: 46310
A9: 銀行業 | B9: 台新銀行 | C9: 台新新光金 | D9: 防範詐騙：以圖演算法追蹤多層次金流與可疑帳戶，結合機器學習辨識詐騙模式。 | E9: 阻詐 | F9: 46310
A10: 銀行業 | B10: 台新銀行 | C10: 台新新光金 | D10: 智能質檢：導入 ASR 語音辨識與 LLM，建構自動化質檢流程，實現音檔轉譯文本等作業。 | E10: 語音質檢/應用 | F10: 46310
A11: 銀行業 | B11: 台新銀行 | C11: 台新新光金 | D11: 智能小幫手：建立智能知識管理平台，提供內部員工語意式智能搜尋問答（原文未明示 RAG）。 | E11: RAG/KM | F11: 46310
A12: 銀行業 | B12: 彰化銀行 | C12: 未歸類 | D12: 「鷹眼 AI 防詐模型」：搭配「疑似不法顯屬異常」兩項 Rule-based 風險態樣指標，每日自動設控高風險存款帳戶，並保留人工審核、介入及解控救濟機制。 | E12: 阻詐 | F12: 46310
A13: 銀行業 | B13: 將來銀行 | C13: 未歸類 | D13: 「AI 小將」文字客服：提供 24×7 服務，涵蓋既有產品，原文載明覆蓋率（精準度）達 97.6%。 | E13: 智能客服 | F13: 46310
... A168: 證券期貨業 | B168: 國票綜合證券 | C168: 國票金 | D168: 自主研發「國票任我贏」App，導入專利「申購易智抽」智慧條件自動比對與雲端智慧單，獲 2026 國家品牌玉山獎最佳產品類。 | E168: App | F168: 46317

Sheet 來源索引
A1: 業別 | B1: 業者 | C1: PDF頁碼 | D1: 場景筆數 | F1: 業別下拉選項 | G1: 業者下拉選項 | H1: 所屬金控下拉選項
A2: 銀行業 | B2: 富邦金控 | C2: 1 | D2: =COUNTIFS(AI應用場景!A:A,A2,AI應用場景!B:B,B2) -> 3 | F2: {=_xlfn._xlws.SORT(_xlfn.UNIQUE(業者來源索引[業別]))} -> 保險業 | G2: {=_xlfn._xlws.SORT(_xlfn.UNIQUE(業者來源索引[業者]))} -> 口袋證券 | H2: 元大金
A3: 銀行業 | B3: 臺灣金控 | C3: 1 | D3: =COUNTIFS(AI應用場景!A:A,A3,AI應用場景!B:B,B3) -> 1 | F3: 銀行業 | G3: 大昌證券 | H3: 富邦金
A4: 銀行業 | B4: 玉山金控 | C4: 1 | D4: =COUNTIFS(AI應用場景!A:A,A4,AI應用場景!B:B,B4) -> 1 | F4: 證券期貨業 | G4: 中信產險 | H4: 國泰金
A5: 銀行業 | B5: 王道銀行 | C5: 1 | D5: =COUNTIFS(AI應用場景!A:A,A5,AI應用場景!B:B,B5) -> 1 | G5: 中國信託銀行 | H5: 中信金
A6: 銀行業 | B6: 連線銀行 | C6: 1 | D6: =COUNTIFS(AI應用場景!A:A,A6,AI應用場景!B:B,B6) -> 1 | G6: 元大人壽 | H6: 凱基金
A7: 銀行業 | B7: 台新銀行 | C7: 1 | D7: =COUNTIFS(AI應用場景!A:A,A7,AI應用場景!B:B,B7) -> 7 | G7: 元大銀行 | H7: 永豐金
A8: 銀行業 | B8: 彰化銀行 | C8: 1 | D8: =COUNTIFS(AI應用場景!A:A,A8,AI應用場景!B:B,B8) -> 1 | G8: 元大證券 | H8: 台新新光金
A9: 銀行業 | B9: 將來銀行 | C9: 1 | D9: =COUNTIFS(AI應用場景!A:A,A9,AI應用場景!B:B,B9) -> 1 | G9: 公勝保險經紀人股份有限公司 | H9: 玉山金
A10: 銀行業 | B10: 渣打銀行 | C10: 1 | D10: =COUNTIFS(AI應用場景!A:A,A10,AI應用場景!B:B,B10) -> 1 | G10: 友邦人壽 | H10: 兆豐金
A11: 銀行業 | B11: 華南銀行 | C11: 2 | D11: =COUNTIFS(AI應用場景!A:A,A11,AI應用場景!B:B,B11) -> 6 | G11: 王道銀行 | H11: 第一金
A12: 銀行業 | B12: 台中銀行 | C12: 2 | D12: =COUNTIFS(AI應用場景!A:A,A12,AI應用場景!B:B,B12) -> 1 | G12: 台中銀行 | H12: 華南金
A13: 銀行業 | B13: 臺灣銀行 | C13: 2 | D13: =COUNTIFS(AI應用場景!A:A,A13,AI應用場景!B:B,B13) -> 2 | G13: 台北富邦銀行 | H13: 合庫金
A14: 銀行業 | B14: 玉山銀行 | C14: 2 | D14: =COUNTIFS(AI應用場景!A:A,A14,AI應用場景!B:B,B14) -> 1 | G14: 台新銀行 | H14: 國票金
A15: 銀行業 | B15: 元大銀行 | C15: 2 | D15: =COUNTIFS(AI應用場景!A:A,A15,AI應用場景!B:B,B15) -> 2 | G15: 台新證券 | H15: 臺灣金
A16: 銀行業 | B16: 國泰世華銀行 | C16: 2 | D16: =COUNTIFS(AI應用場景!A:A,A16,AI應用場景!B:B,B16) -> 3 | G16: 台灣人壽 | H16: 未歸類
A17: 銀行業 | B17: 滙豐銀行 | C17: 2 | D17: =COUNTIFS(AI應用場景!A:A,A17,AI應用場景!B:B,B17) -> 1 | G17: 永達保險經紀人股份有限公司
A18: 銀行業 | B18: 臺灣中小企銀 | C18: 2 | D18: =COUNTIFS(AI應用場景!A:A,A18,AI應用場景!B:B,B18) -> 1 | G18: 永豐投顧
A19: 銀行業 | B19: 中國信託銀行 | C19: 2 | D19: =COUNTIFS(AI應用場景!A:A,A19,AI應用場景!B:B,B19) -> 5 | G19: 永豐金證券
A20: 銀行業 | B20: 台北富邦銀行 | C20: 2–3 | D20: =COUNTIFS(AI應用場景!A:A,A20,AI應用場景!B:B,B20) -> 6 | G20: 永豐銀行
A21: 銀行業 | B21: 樂天銀行 | C21: 3 | D21: =COUNTIFS(AI應用場景!A:A,A21,AI應用場景!B:B,B21) -> 1 | G21: 玉山金控
A22: 銀行業 | B22: 全盈支付 | C22: 3 | D22: =COUNTIFS(AI應用場景!A:A,A22,AI應用場景!B:B,B22) -> 1 | G22: 玉山銀行
A23: 銀行業 | B23: 全支付公司 | C23: 3 | D23: =COUNTIFS(AI應用場景!A:A,A23,AI應用場景!B:B,B23) -> 2 | G23: 玉山證券
A24: 銀行業 | B24: 金融研訓院 | C24: 3 | D24: =COUNTIFS(AI應用場景!A:A,A24,AI應用場景!B:B,B24) -> 1 | G24: 兆豐產險
A25: 銀行業 | B25: 存保公司 | C25: 3 | D25: =COUNTIFS(AI應用場景!A:A,A25,AI應用場景!B:B,B25) -> 4 | G25: 兆豐銀行
A26: 銀行業 | B26: 聯卡中心 | C26: 3 | D26: =COUNTIFS(AI應用場景!A:A,A26,AI應用場景!B:B,B26) -> 2 | G26: 全支付公司
A27: 保險業 | B27: 國泰人壽 | C27: 3 | D27: =COUNTIFS(AI應用場景!A:A,A27,AI應用場景!B:B,B27) -> 4 | G27: 全盈支付
A28: 保險業 | B28: 新光人壽 | C28: 3 | D28: =COUNTIFS(AI應用場景!A:A,A28,AI應用場景!B:B,B28) -> 4 | G28: 全球人壽
A29: 保險業 | B29: 友邦人壽 | C29: 3 | D29: =COUNTIFS(AI應用場景!A:A,A29,AI應用場景!B:B,B29) -> 1 | G29: 合作金庫銀行
A30: 保險業 | B30: 台灣人壽 | C30: 3 | D30: =COUNTIFS(AI應用場景!A:A,A30,AI應用場景!B:B,B30) -> 3 | G30: 存保公司
A31: 保險業 | B31: 富邦人壽 | C31: 3–4 | D31: =COUNTIFS(AI應用場景!A:A,A31,AI應用場景!B:B,B31) -> 7 | G31: 和安保險代理人股份有限公司
A32: 保險業 | B32: 元大人壽 | C32: 4 | D32: =COUNTIFS(AI應用場景!A:A,A32,AI應用場景!B:B,B32) -> 2 | G32: 東方匯理投信
A33: 保險業 | B33: 凱基人壽 | C33: 4 | D33: =COUNTIFS(AI應用場景!A:A,A33,AI應用場景!B:B,B33) -> 3 | G33: 法盛投顧
A34: 保險業 | B34: 全球人壽 | C34: 4 | D34: =COUNTIFS(AI應用場景!A:A,A34,AI應用場景!B:B,B34) -> 1 | G34: 金融研訓院
A35: 保險業 | B35: 南山人壽 | C35: 4 | D35: =COUNTIFS(AI應用場景!A:A,A35,AI應用場景!B:B,B35) -> 4 | G35: 阿爾發投顧
A36: 保險業 | B36: 保誠人壽 | C36: 4 | D36: =COUNTIFS(AI應用場景!A:A,A36,AI應用場景!B:B,B36) -> 1 | G36: 保誠人壽
A37: 保險業 | B37: 科隆再保公司 | C37: 4 | D37: =COUNTIFS(AI應用場景!A:A,A37,AI應用場景!B:B,B37) -> 1 | G37: 南山人壽
A38: 保險業 | B38: 中信產險 | C38: 4 | D38: =COUNTIFS(AI應用場景!A:A,A38,AI應用場景!B:B,B38) -> 1 | G38: 科法斯產險
A39: 保險業 | B39: 科法斯產險 | C39: 4 | D39: =COUNTIFS(AI應用場景!A:A,A39,AI應用場景!B:B,B39) -> 1 | G39: 科隆再保公司
A40: 保險業 | B40: 國泰產險 | C40: 4 | D40: =COUNTIFS(AI應用場景!A:A,A40,AI應用場景!B:B,B40) -> 1 | G40: 美商達信保險經紀人股份有限公司台灣分公司
...

Sheet 分類說明
A1: 台灣金融業 AI 應用｜分類說明 | F1: 所屬金控｜名稱關鍵字歸類
A2: 來源：各業者AI應用 1.pdf，附件二，全文 7 頁；資料由金融機構及周邊單位自行提供。 | F2: 依指定14組名稱關鍵字重新歸類，多項符合時依表列順序優先；未符合者標為「未歸類」，不代表已確認無金控隸屬。結果以分類值保存，可透過主表下拉選單手動調整。
A4: 類別 | B4: 判斷原則 | C4: 界線與注意事項 | D4: 場景筆數 | F4: 關鍵字 1 | G4: 其他關鍵字（或） | H4: 所屬金控 | I4: 場景筆數
A5: RAG/KM | B5: 結合文件／知識檢索與生成回答。 | C5: 台中銀行、口袋證券原文明示 RAG；華南銀行、國泰世華銀行員工助手、達信、聯博依用途推定，並非技術驗證。 | D5: =COUNTIF(AI應用場景!E:E,A5) -> 10 | F5: 元大 | H5: 元大金 | I5: =COUNTIF(金融業AI場景明細[所屬金控],H5) -> 5
A6: 語音質檢/應用 | B6: 語音轉文字、文字轉語音、錄音／語音質檢，以及明示語音辨識、IVR、語音機器人或語音自助服務的應用。 | C6: 語音相關用途優先於 RPA、智能客服等分類；錄音質檢不須明示轉文字即可納入。語音服務不代表已驗證 STT／TTS 技術；僅通話摘要或 AI 播報且未明示語音轉換／質檢者不逕行納入。 | D6: =COUNTIF(AI應用場景!E:E,A6) -> 12 | F6: 富邦 | H6: 富邦金 | I6: =COUNTIF(金融業AI場景明細[所屬金控],H6) -> 21
A7: 生成式AI | B7: 內容、摘要、報告、影音生成，以及明示 LLM 的內容處理；程式／SQL 開發輔助另歸程式助手。 | C7: 亦包含依角色對練、報告產出等用途推定者；不是每項都由原文明示生成式技術。 | D7: =COUNTIF(AI應用場景!E:E,A7) -> 35 | F7: 國泰 | G7: 國泰世華 | H7: 國泰金 | I7: =COUNTIF(金融業AI場景明細[所屬金控],H7) -> 10
A8: 比對 | B8: 以法規關聯、威脅情資或文件適法性比較為主要用途。 | C8: 不將所有風險模型、審查、保單健診或 eKYC 一律視為比對。 | D8: =COUNTIF(AI應用場景!E:E,A8) -> 3 | F8: 中信 | G8: 中國信託、台灣人壽 | H8: 中信金 | I8: =COUNTIF(金融業AI場景明細[所屬金控],H8) -> 9
A9: 阻詐 | B9: 明確用於詐欺偵測、識詐、聯防或阻擋詐騙。 | C9: 一般風險評級、反洗錢、異常交易、資安及理賠異常，不在未明示詐欺時直接歸入。 | D9: =COUNTIF(AI應用場景!E:E,A9) -> 22 | F9: 凱基 | G9: 開發 | H9: 凱基金 | I9: =COUNTIF(金融業AI場景明細[所屬金控],H9) -> 6
A10: M365 Copilot | B10: 原文提及 Microsoft／微軟 Copilot 或 M365 Copilot 的辦公與生產力應用。 | C10: 將僅稱 Copilot 的辦公應用一併歸此；明示程式開發用途者優先歸程式助手。不憑 Copilot 名稱推定為 GitHub Copilot，版本與授權以原文為準。 | D10: =COUNTIF(AI應用場景!E:E,A10) -> 9 | F10: 永豐 | H10: 永豐金 | I10: =COUNTIF(金融業AI場景明細[所屬金控],H10) -> 6
A11: AI Agent | B11: 原文明確提到 AI 代理人或AI Agent或Agent | C11: 不因名稱含「助理」「機器人」或「AI 投資長」就推定為自主代理。 | D11: =COUNTIF(AI應用場景!E:E,A11) -> 8 | F11: 台新 | G11: 新光 | H11: 台新新光金 | I11: =COUNTIF(金融業AI場景明細[所屬金控],H11) -> 12
A12: OCR | B12: 原文明確使用 AI OCR 進行文件或表單辨識及欄位擷取。 | C12: LLM 單據萃取、AI 審票未明示 OCR 者不自行推定。 | D12: =COUNTIF(AI應用場景!E:E,A12) -> 2 | F12: 玉山 | H12: 玉山金 | I12: =COUNTIF(金融業AI場景明細[所屬金控],H12) -> 3
A13: 智能客服 | B13: 以對客服務、諮詢問答、語音對話、IVR 或電訪機器人為主要用途。 | C13: 對客服務原則歸此；明示語音辨識、IVR、語音機器人、語音自助服務或語音質檢者，優先歸語音質檢/應用；內部助理不直接歸客服。 | D13: =COUNTIF(AI應用場景!E:E,A13) -> 12 | F13: 兆豐 | H13: 兆豐金 | I13: =COUNTIF(金融業AI場景明細[所屬金控],H13) -> 3
A14: 程式助手 | B14: GitHub Copilot 或其它輔助程式／SQL 撰寫、軟體開發、編譯、測試修復或 debug 的應用。 | C14: 明示程式開發用途者優先歸此，含混合辦公用途及 Text-to-SQL；僅提供 API 或泛稱支援開發團隊不足以判入。現有場景未明示 GitHub Copilot。 | D14: =COUNTIF(AI應用場景!E:E,A14) -> 5 | F14: 第一 | H14: 第一金 | I14: =COUNTIF(金融業AI場景明細[所屬金控],H14) -> 2
A15: RPA | B15: 依指定口徑，場景明示 RPA 或流程自動化即歸此，含徵審自動化；語音質檢／應用優先另分類。 | C15: 本分類採用途口徑，不代表均採傳統 RPA 技術；語音自動化質檢改歸語音質檢/應用。僅自動生成、摘要、辨識、設控或泛稱效率提升，不直接判入。 | D15: =COUNTIF(AI應用場景!E:E,A15) -> 6 | F15: 華南 | H15: 華南金 | I15: =COUNTIF(金融業AI場景明細[所屬金控],H15) -> 7
A16: 模型訓練 | B16: 依指定口徑，將本次調整前類別為「其它」，且場景文字含「模型」的項目歸入。 | C16: 依文字條件分類，包含模型預測、排序及風險應用；不代表原文已明示模型訓練用途。 | D16: =COUNTIF(AI應用場景!E:E,A16) -> 7 | F16: 合庫 | H16: 合庫金 | I16: =COUNTIF(金融業AI場景明細[所屬金控],H16) -> 2
A17: App | B17: 場景描述與 App 有關者歸入此類。 | C17: 場景描述只要提及「App」即歸入此類；亦可由使用者手動將場景類別指定為 App。 | D17: =COUNTIF(AI應用場景!E:E,A17) -> 5 | F17: 國票 | H17: 國票金 | I17: =COUNTIF(金融業AI場景明細[所屬金控],H17) -> 1
A18: 其它 | B18: 預測、排序、評分、基礎架構，或資訊不足的應用；明示 RPA／流程自動化者另歸 RPA；本次原為其它且場景含「模型」者改歸模型訓練。 | C18: 保留原文概括敘述，不自行補寫不存在的細節；「其它」不代表不使用 AI。 | D18: =COUNTIF(AI應用場景!E:E,A18) -> 31 | F18: 臺銀 | G18: 臺灣銀行、臺灣金控 | H18: 臺灣金 | I18: =COUNTIF(金融業AI場景明細[所屬金控],H18) -> 3
A19: 合計場景 | D19: =SUM(D5:D18) -> 167 | F19: 未符合上述關鍵字 | H19: 未歸類 | I19: =COUNTIF(金融業AI場景明細[所屬金控],H19) -> 77
F20: 合計場景 | I20: =SUM(I5:I19) -> 167
A21: 整理口徑與資料限制
A22: ="整理單位：共 80 個業者／周邊單位、"&D19&" 筆場景；保留原文業別及出現順序，不依業者名稱重新推定監理業別。" -> 整理單位：共 80 個業者／周邊單位、167 筆場景；保留原文業別及出現順序，不依業者名稱重新推定監理業別。
A23: 拆分原則：每列為一個可獨立辨識的用途；同一產品若涵蓋不同功能可拆列。同一 Copilot 辦公套件的常見工作則合併敘述，筆數不等於系統數或成熟度。 全盈支付依指定將軟體開發、資料庫語言審查及白箱測試風險修復合併為一筆，歸類為程式助手。 富邦證券依指定將 AI 投資助理的市場問答、美股法說會摘要及每日盤前資訊播報合併為一筆，歸類為生成式AI。 永豐金證券依指定將個股 AI 市場輿情分析及每日投資早報合併為一筆，歸類為生成式AI。 統一期貨依指定將資料整理、簡報生成及複雜文件處理合併為一筆，歸類為 M365 Copilot。 富邦期貨依指定將「富邦 AI PRO」投資問答、法說會摘要、AI 主播盤前播報及個人化資訊推送合併為一筆，並依使用者指定改歸 App。 聯博投信依指定將 ABAI 的文件資料聊天查詢、資料抽取、文件比較、圖表生成、Text-to-SQL 及安全 API 支援合併為一筆，歸類為其它；其餘場景保留。
A24: 單一分類：每筆只選一個主要類別；語音轉文字、文字轉語音、錄音／語音質檢及明示語音辨識／服務者優先歸語音質檢/應用；其後依 RPA／流程自動化、程式助手及其餘主要用途分類。
A25: 推定標註：主表部分列依用途推定技術類別；RAG 等標籤是整理判斷，不代表對業者技術架構進行查證。
A26: 產品名稱：除原文明示 M365 者外，Copilot 的版本與授權不明；純辦公用途歸 M365 Copilot，明示程式開發用途歸程式助手；本次未將任何場景自行推定為 GitHub Copilot。
A27: 資料限制：原文未詳述的場景仍予保留並註明；未引入外部資料。原文所列精準度、減量比例等為業者自行提供，未獨立驗證。
A28: 來源回查：請於「來源索引」以業者查找 PDF 頁碼；跨頁項目標為 2–3、3–4、5–6。PDF 頁序與本附件印刷頁碼一致。
A29: 使用方式：主表可依業別、業者及類別篩選；來源索引與本表的場景筆數以公式連結主表，後續修改分類時會重新計算。
